Workbook
Name DATA_CLEANING: Table2[]
Name Slicer_Category: #N/A
Name Slicer_Region: #N/A
Name Slicer_Segment: #N/A
Name Slicer_YEAR: #N/A

Sheet Raw_Sales_Data
A1: Order ID | B1: Order Date | C1: Customer ID | D1: Segment | E1: Region | F1: Category | G1: Product | H1: Quantity | I1: Unit Price | J1: Sales Amount
A2: ORD-1000 | B2: 45619 | C2: CUST-106 | D2: Consumer | E2: North | F2: Electronics | G2: Tablet | H2: 4 | I2: $78.37
A3: ORD-1001 | B3: 45638 | C3: CUST-113 | D3: Corporate | E3: Central | F3: Electronics | G3: Headphones | H3: 1 | I3: $24.6
A4: ORD-1002 | B4: 45411 | C4: CUST-144 | D4: Home Office | E4: Central | F4: Toys | G4: Action Figure | H4: 4 | I4: $360.85
A5: ORD-1003 | B5: 45571 | C5: CUST-100 | D5: Home Office | E5: West | F5: Clothing | G5: Sweater | H5: 5 | I5: $406.62
A6: ORD-1004 | B6: 45373 | C6: CUST-121 | D6: Consumer | E6: West | F6: Home & Kitchen | G6: Coffee Maker | H6: 4 | I6: $479.03
A7: ORD-1005 | B7: 45344 | C7: CUST-116 | D7: Corporate | E7: North | F7: Office Supplies | G7: Stapler | H7: 14 | I7: $178.54
A8: ORD-1006 | B8: 45314 | C8: CUST-140 | D8: Corporate | E8: West | F8: Toys | G8: Action Figure | H8: 2 | I8: $280.5
A9: ORD-1007 | B9: 45608 | C9: CUST-114 | D9: Home Office | E9: East | F9: Toys | G9: Board Game | H9: 2 | I9: $32.45
A10: ORD-1008 | B10: 45440 | C10: CUST-123 | D10: Corporate | E10: North | F10: Clothing | G10: T-Shirt | H10: 5 | I10: $232.17
A11: ORD-1009 | B11: 45375 | C11: CUST-143 | D11: Home Office | E11: East | F11: home & kitchen | G11: Toaster | H11: 5 | I11: $353.89
A12: ORD-1010 | B12: 45623 | C12: CUST-129 | D12: Home Office | E12: North | F12: Toys | G12: Board Game | H12: 12 | I12: $129.96
A13: ORD-1011 | B13: 45486 | C13: CUST-149 | D13: Home Office | E13: East | F13: Toys | G13: Board Game | H13: 6 | I13: $423
... A56: ORD-1054 | B56: 45375 | C56: CUST-150 | D56: Consumer | E56: South | F56: Office Supplies | G56: Stapler | H56: 12 | I56: $463
A57: ORD-1055 | B57: 45502 | C57: CUST-102 | E57: South | F57: Home & Kitchen | G57: Toaster | H57: 2 | I57: $197.45
A58: ORD-1056 | B58: 45532 | C58: CUST-114 | E58: South | F58: Clothing | G58: Sweater | H58: 5 | I58: $412.06
A59: ORD-1057 | B59: 45406 | C59: CUST-149 | D59: Corporate | E59: North | F59: Clothing | G59: Sweater | H59: 5 | I59: $433.53
A60: ORD-1058 | B60: 45434 | C60: CUST-101 | D60: Home Office | E60: East | F60: Toys | G60: Lego Set | H60: 14 | I60: $272.75
A61: ORD-1059 | B61: 45351 | C61: CUST-127 | D61: Corporate | E61: East | F61: Clothing | G61: Socks | H61: 1 | I61: $63.12
A62: ORD-1060 | B62: 45468 | C62: CUST-136 | D62: Home Office | E62: East | F62: Office Supplies | G62: Paper Shredder | H62: 2 | I62: $198.75
A63: ORD-1061 | B63: 45389 | C63: CUST-134 | E63: East | F63: Electronics | G63: Monitor | H63: 9 | I63: $463.53
A64: ORD-1062 | B64: 45643 | C64: CUST-139 | D64: Consumer | E64: South | F64: Home & Kitchen | G64: Vacuum | H64: 11 | I64: $461.18
A65: ORD-1063 | B65: 45452 | C65: CUST-125 | D65: Corporate | E65: North | F65: Home & Kitchen | G65: Air Fryer | H65: 11 | I65: $210.11
A66: ORD-1064 | B66: 45648 | C66: CUST-124 | D66: Consumer | E66: East | F66: Toys | G66: Board Game | H66: 7 | I66: $335.82
A67: ORD-1065 | B67: 45638 | C67: CUST-100 | D67: Corporate | E67: South | F67: toys | G67: Doll | H67: 7 | I67: $278.49
A68: ORD-1066 | B68: 45447 | C68: CUST-129 | D68: Home Office | E68: East | F68: Clothing | G68: Sweater | H68: 10 | I68: $330.81
A69: ORD-1067 | B69: 45518 | C69: CUST-150 | D69: Corporate | E69: West | F69: Clothing | G69: Socks | H69: 13 | I69: $451.58
A70: ORD-1068 | B70: 45378 | C70: CUST-105 | D70: Home Office | E70: North | F70: home & kitchen | G70: Air Fryer | H70: 11 | I70: $313.44
A71: ORD-1069 | B71: 45412 | C71: CUST-130 | D71: Consumer | E71: East | F71: Clothing | G71: Jeans | H71: 1 | I71: $32.64
A72: ORD-1070 | B72: 45604 | C72: CUST-144 | D72: Home Office | E72: North | F72: Office Supplies | G72: Desk Lamp | H72: 10 | I72: $105.27
A73: ORD-1071 | B73: 45488 | C73: CUST-148 | D73: Consumer | E73: West | F73: Office Supplies | G73: Notebook | H73: 11 | I73: $346.93
A74: ORD-1072 | B74: 45346 | C74: CUST-135 | D74: Home Office | E74: West | F74: Clothing | G74: Jeans | H74: 9 | I74: $237.63
A75: ORD-1073 | B75: 45419 | C75: CUST-135 | D75: Corporate | E75: North | F75: office supplies | G75: Notebook | H75: 11 | I75: $270.25
... A106: ORD-1104 | B106: 45448 | C106: CUST-147 | D106: Home Office | E106: East | F106: Clothing | G106: T-Shirt | H106: 4 | I106: $164.62
A107: ORD-1105 | B107: 45566 | C107: CUST-137 | E107: South | F107: Clothing | G107: Jeans | H107: 8 | I107: $145.48
A108: ORD-1106 | B108: 45560 | C108: CUST-111 | D108: Consumer | E108: Central | F108: Home & Kitchen | G108: Blender | H108: 5 | I108: $121.47
A109: ORD-1107 | B109: 45446 | C109: CUST-135 | D109: Corporate | E109: North | F109: Toys | G109: Board Game | H109: 1 | I109: $487.4
A110: ORD-1108 | B110: 45441 | C110: CUST-130 | D110: Consumer | E110: South | F110: Office Supplies | G110: Stapler | H110: 10 | I110: $149.33
A111: ORD-1109 | B111: 45517 | C111: CUST-104 | D111: Corporate | E111: East | F111: Clothing | G111: T-Shirt | H111: 14 | I111: $244.09
A112: ORD-1110 | B112: 45497 | C112: CUST-109 | D112: Home Office | E112: West | F112: Electronics | G112: Headphones | H112: 11 | I112: $36.27
...

Sheet PIVOT_TOTAL_SALES
A1: YEAR | B1: (All)
B3: Column Labels
B4: Central | D4: East | F4: North | H4: South | J4: West | L4: Total Sum of Sales Amount | M4: Total Sum of YEAR
A5: Row Labels | B5: Sum of Sales Amount | C5: Sum of YEAR | D5: Sum of Sales Amount | E5: Sum of YEAR | F5: Sum of Sales Amount | G5: Sum of YEAR | H5: Sum of Sales Amount | I5: Sum of YEAR | J5: Sum of Sales Amount | K5: Sum of YEAR
A6: Clothing | B6: 23905.42 | C6: 18220 | D6: 8232.82 | E6: 14174 | F6: 24391.25 | G6: 22272 | H6: 11909.22 | I6: 22273 | J6: 16449.11 | K6: 14174 | L6: 84887.82 | M6: 91113
A7: Electronics | B7: 10608.64 | C7: 16199 | D7: 11251.21 | E7: 16200 | F7: 19359.7 | G7: 18223 | H7: 10630.85 | I7: 20245 | J7: 10697.81 | K7: 12150 | L7: 62548.21 | M7: 83017
A8: Home & Kitchen | B8: 7964.15 | C8: 10124 | D8: 21359.33 | E8: 16198 | F8: 22157.75 | G8: 14174 | H8: 21879.94 | I8: 16199 | J8: 20732.74 | K8: 26324 | L8: 94093.91 | M8: 83019
A9: Office Supplies | B9: 14966.53 | C9: 16200 | D9: 15229.62 | E9: 14174 | F9: 28350.29 | G9: 22274 | H9: 18295.73 | I9: 16198 | J9: 21923.82 | K9: 14175 | L9: 98765.99 | M9: 83021
A10: Toys | B10: 21898.21 | C10: 18222 | D10: 13586.19 | E10: 14173 | F10: 12305.11 | G10: 14172 | H10: 28659.45 | I10: 20250 | J10: 6363.13 | K10: 8099 | L10: 82812.09 | M10: 74916
A11: Grand Total | B11: 79342.95 | C11: 78965 | D11: 69659.17 | E11: 74919 | F11: 106564.1 | G11: 91115 | H11: 91375.19 | I11: 95165 | J11: 76166.61 | K11: 74922 | L11: 423108.02 | M11: 415086

Sheet AVG_QUANTITY_SOLD
A3: Average of Quantity | B3: Column Labels
A4: Row Labels | B4: Central | C4: East | D4: North | E4: South | F4: West | G4: Grand Total
A5: Consumer | B5: 6.5833333 | C5: 7 | D5: 9.6363636 | E5: 9.5 | F5: 7.9 | G5: 8.3333333
A6: Corporate | B6: 10.777778 | C6: 8.1333333 | D6: 8.1 | E6: 9.7692308 | F6: 7.5384615 | G6: 8.75
A7: Home Office | B7: 8.625 | C7: 7.75 | D7: 10 | E7: 8.4 | F7: 7.6363636 | G7: 8.5454545
A8: Grand Total | B8: 8.4482759 | C8: 7.8387097 | D8: 9.3428571 | E8: 9.2972973 | F8: 7.6764706 | G8: 8.5542169

Sheet LINE_CHART
A3: Row Labels | B3: Sum of Sales Amount
A4: 2024 | B4: 63951.78
A5: 11 | B5: 8909.94
A6: 12 | B6: 55041.84
A7: 2025 | B7: 359156.24
A8: 1 | B8: 82634.47
A9: 2 | B9: 65546.17
A10: 3 | B10: 51335.83
A11: 4 | B11: 78103.82
A12: 5 | B12: 64398.97
A13: 6 | B13: 17136.98
A14: Grand Total | B14: 423108.02

Sheet  Bar_Chart
A3: Row Labels | B3: Sum of Sales Amount
A4: Air Fryer | B4: 37491.69
A5: Lego Set | B5: 29341.14
A6: Monitor | B6: 22852.58
A7: Pen Set | B7: 21892.23
A8: Stapler | B8: 26942.79
A9: Grand Total | B9: 138520.43

Sheet DATA_CLEANING
A1: Order ID | B1: Order Date | C1: Customer ID | D1: Segment | E1: Region | F1: Category | G1: Product | H1: Quantity | I1: Unit Price | J1: Sales Amount | K1: YEAR | L1: Month | M1: Day of Week | N1: Product Cost(VL) | O1: PRODUCT COST | P1: PROFIT
A2: Order ID | B2: Order Date | C2: Customer ID | D2: Segment | E2: Region | F2: Category | G2: Product | H2: Quantity | I2: Unit Price | J2: Sales Amount | K2: YEAR | L2: Month | M2: Day of Week | N2: Product Cost(VL) | O2: PRODUCT COST | P2: PROFIT | V2: BASIC ANALYSIS
A3: ORD-1000 | B3: 45619 | C3: CUST-106 | D3: Consumer | E3: North | F3: Electronics | G3: Tablet | H3: 4 | I3: 78.37 | J3: =I3*H3 -> 313.48 | K3: =YEAR(Table2[[#This Row],[Order Date]]) -> 2024 | L3: =MONTH(Table2[[#This Row],[Order Date]]) -> 11 | M3: =WEEKDAY(Table2[[#This Row],[Order Date]]) -> 7 | N3: =VLOOKUP(Table2[[#This Row],[Product]], Product_Lookup!$A$2:$B$26, 2, FALSE) -> 146.06 | O3: =Table2[[#This Row],[Product Cost(VL)]]*Table2[[#This Row],[Quantity]] -> 584.24 | P3: =Table2[[#This Row],[Sales Amount]]-Table2[[#This Row],[ PRODUCT COST]] -> -270.76 | V3: Total Sales Amount | W3: =SUM(Table2[Sales Amount]) -> 423108.02
A4: ORD-1001 | B4: 45620 | C4: CUST-107 | D4: Corporate | E4: Central | F4: Electronics | G4: Headphones | H4: 1 | I4: 78.38 | J4: =I4*H4 -> 78.38 | K4: =YEAR(Table2[[#This Row],[Order Date]]) -> 2024 | L4: =MONTH(Table2[[#This Row],[Order Date]]) -> 11 | M4: =WEEKDAY(Table2[[#This Row],[Order Date]]) -> 1 | N4: =VLOOKUP(Table2[[#This Row],[Product]], Product_Lookup!$A$2:$B$26, 2, FALSE) -> 178.83 | O4: =Table2[[#This Row],[Product Cost(VL)]]*Table2[[#This Row],[Quantity]] -> 178.83 | P4: =Table2[[#This Row],[Sales Amount]]-Table2[[#This Row],[ PRODUCT COST]] -> -100.45 | V4: Average Order Value | W4: =AVERAGE(Table2[Sales Amount]) -> 2063.9416
A5: ORD-1002 | B5: 45621 | C5: CUST-108 | D5: Home Office | E5: Central | F5: Toys | G5: Action Figure | H5: 4 | I5: 360.85 | J5: =I5*H5 -> 1443.4 | K5: =YEAR(Table2[[#This Row],[Order Date]]) -> 2024 | L5: =MONTH(Table2[[#This Row],[Order Date]]) -> 11 | M5: =WEEKDAY(Table2[[#This Row],[Order Date]]) -> 2 | N5: =VLOOKUP(Table2[[#This Row],[Product]], Product_Lookup!$A$2:$B$26, 2, FALSE) -> 88.18 | O5: =Table2[[#This Row],[Product Cost(VL)]]*Table2[[#This Row],[Quantity]] -> 352.72 | P5: =Table2[[#This Row],[Sales Amount]]-Table2[[#This Row],[ PRODUCT COST]] -> 1090.68 | V5: Number of Unique Products Sold | W5: =COUNTA(UNIQUE(Table2[Product])) -> 1
A6: ORD-1003 | B6: 45622 | C6: CUST-109 | D6: Home Office | E6: West | F6: Clothing | G6: Sweater | H6: 5 | I6: 406.62 | J6: =I6*H6 -> 2033.1 | K6: =YEAR(Table2[[#This Row],[Order Date]]) -> 2024 | L6: =MONTH(Table2[[#This Row],[Order Date]]) -> 11 | M6: =WEEKDAY(Table2[[#This Row],[Order Date]]) -> 3 | N6: =VLOOKUP(Table2[[#This Row],[Product]], Product_Lookup!$A$2:$B$26, 2, FALSE) -> 84.57 | O6: =Table2[[#This Row],[Product Cost(VL)]]*Table2[[#This Row],[Quantity]] -> 422.85 | P6: =Table2[[#This Row],[Sales Amount]]-Table2[[#This Row],[ PRODUCT COST]] -> 1610.25 | V6: Number of Orders | W6: =COUNTA(Table2[Order ID]) -> 205
A7: ORD-1004 | B7: 45623 | C7: CUST-110 | D7: Consumer | E7: West | F7: Home & Kitchen | G7: Coffee Maker | H7: 4 | I7: 479.03 | J7: =I7*H7 -> 1916.12 | K7: =YEAR(Table2[[#This Row],[Order Date]]) -> 2024 | L7: =MONTH(Table2[[#This Row],[Order Date]]) -> 11 | M7: =WEEKDAY(Table2[[#This Row],[Order Date]]) -> 4 | N7: =VLOOKUP(Table2[[#This Row],[Product]], Product_Lookup!$A$2:$B$26, 2, FALSE) -> 230.34 | O7: =Table2[[#This Row],[Product Cost(VL)]]*Table2[[#This Row],[Quantity]] -> 921.36 | P7: =Table2[[#This Row],[Sales Amount]]-Table2[[#This Row],[ PRODUCT COST]] -> 994.76 | V7: Median Quantity Sold per order | W7: =MEDIAN(Table2[Quantity]) -> 8
A8: ORD-1005 | B8: 45624 | C8: CUST-111 | D8: Corporate | E8: North | F8: Office Supplies | G8: Stapler | H8: 14 | I8: 178.54 | J8: =I8*H8 -> 2499.56 | K8: =YEAR(Table2[[#This Row],[Order Date]]) -> 2024 | L8: =MONTH(Table2[[#This Row],[Order Date]]) -> 11 | M8: =WEEKDAY(Table2[[#This Row],[Order Date]]) -> 5 | N8: =VLOOKUP(Table2[[#This Row],[Product]], Product_Lookup!$A$2:$B$26, 2, FALSE) -> 64.61 | O8: =Table2[[#This Row],[Product Cost(VL)]]*Table2[[#This Row],[Quantity]] -> 904.54 | P8: =Table2[[#This Row],[Sales Amount]]-Table2[[#This Row],[ PRODUCT COST]] -> 1595.02
A9: ORD-1006 | B9: 45625 | C9: CUST-112 | D9: Corporate | E9: West | F9: Toys | G9: Action Figure | H9: 2 | I9: 280.5 | J9: =I9*H9 -> 561 | K9: =YEAR(Table2[[#This Row],[Order Date]]) -> 2024 | L9: =MONTH(Table2[[#This Row],[Order Date]]) -> 11 | M9: =WEEKDAY(Table2[[#This Row],[Order Date]]) -> 6 | N9: =VLOOKUP(Table2[[#This Row],[Product]], Product_Lookup!$A$2:$B$26, 2, FALSE) -> 88.18 | O9: =Table2[[#This Row],[Product Cost(VL)]]*Table2[[#This Row],[Quantity]] -> 176.36 | P9: =Table2[[#This Row],[Sales Amount]]-Table2[[#This Row],[ PRODUCT COST]] -> 384.64
A10: ORD-1007 | B10: 45626 | C10: CUST-113 | D10: Home Office | E10: East | F10: Toys | G10: Board Game | H10: 2 | I10: 32.45 | J10: =I10*H10 -> 64.9 | K10: =YEAR(Table2[[#This Row],[Order Date]]) -> 2024 | L10: =MONTH(Table2[[#This Row],[Order Date]]) -> 11 | M10: =WEEKDAY(Table2[[#This Row],[Order Date]]) -> 7 | N10: =VLOOKUP(Table2[[#This Row],[Product]], Product_Lookup!$A$2:$B$26, 2, FALSE) -> 86.6 | O10: =Table2[[#This Row],[Product Cost(VL)]]*Table2[[#This Row],[Quantity]] -> 173.2 | P10: =Table2[[#This Row],[Sales Amount]]-Table2[[#This Row],[ PRODUCT COST]] -> -108.3 | V10: TOTAL PRODUCT COST | W10: =SUM(Table2[[ PRODUCT COST]]) -> 212207.49
A11: ORD-1008 | B11: 45627 | C11: CUST-114 | D11: Corporate | E11: North | F11: Clothing | G11: T-Shirt | H11: 5 | I11: 232.17 | J11: =I11*H11 -> 1160.85 | K11: =YEAR(Table2[[#This Row],[Order Date]]) -> 2024 | L11: =MONTH(Table2[[#This Row],[Order Date]]) -> 12 | M11: =WEEKDAY(Table2[[#This Row],[Order Date]]) -> 1 | N11: =VLOOKUP(Table2[[#This Row],[Product]], Product_Lookup!$A$2:$B$26, 2, FALSE) -> 107.34 | O11: =Table2[[#This Row],[Product Cost(VL)]]*Table2[[#This Row],[Quantity]] -> 536.7 | P11: =Table2[[#This Row],[Sales Amount]]-Table2[[#This Row],[ PRODUCT COST]] -> 624.15 | V11: PROFIT | W11: =W3-W10 -> 210900.53
A12: ORD-1009 | B12: 45628 | C12: CUST-115 | D12: Home Office | E12: East | F12: home & kitchen | G12: Toaster | H12: 5 | I12: 353.89 | J12: =I12*H12 -> 1769.45 | K12: =YEAR(Table2[[#This Row],[Order Date]]) -> 2024 | L12: =MONTH(Table2[[#This Row],[Order Date]]) -> 12 | M12: =WEEKDAY(Table2[[#This Row],[Order Date]]) -> 2 | N12: =VLOOKUP(Table2[[#This Row],[Product]], Product_Lookup!$A$2:$B$26, 2, FALSE) -> 208.85 | O12: =Table2[[#This Row],[Product Cost(VL)]]*Table2[[#This Row],[Quantity]] -> 1044.25 | P12: =Table2[[#This Row],[Sales Amount]]-Table2[[#This Row],[ PRODUCT COST]] -> 725.2
A13: ORD-1010 | B13: 45629 | C13: CUST-116 | D13: Home Office | E13: North | F13: Toys | G13: Board Game | H13: 12 | I13: 129.96 | J13: =I13*H13 -> 1559.52 | K13: =YEAR(Table2[[#This Row],[Order Date]]) -> 2024 | L13: =MONTH(Table2[[#This Row],[Order Date]]) -> 12 | M13: =WEEKDAY(Table2[[#This Row],[Order Date]]) -> 3 | N13: =VLOOKUP(Table2[[#This Row],[Product]], Product_Lookup!$A$2:$B$26, 2, FALSE) -> 86.6 | O13: =Table2[[#This Row],[Product Cost(VL)]]*Table2[[#This Row],[Quantity]] -> 1039.2 | P13: =Table2[[#This Row],[Sales Amount]]-Table2[[#This Row],[ PRODUCT COST]] -> 520.32
A14: ORD-1011 | B14: 45630 | C14: CUST-117 | D14: Home Office | E14: East | F14: Toys | G14: Board Game | H14: 6 | I14: 423 | J14: =I14*H14 -> 2538 | K14: =YEAR(Table2[[#This Row],[Order Date]]) -> 2024 | L14: =MONTH(Table2[[#This Row],[Order Date]]) -> 12 | M14: =WEEKDAY(Table2[[#This Row],[Order Date]]) -> 4 | N14: =VLOOKUP(Table2[[#This Row],[Product]], Product_Lookup!$A$2:$B$26, 2, FALSE) -> 86.6 | O14: =Table2[[#This Row],[Product Cost(VL)]]*Table2[[#This Row],[Quantity]] -> 519.6 | P14: =Table2[[#This Row],[Sales Amount]]-Table2[[#This Row],[ PRODUCT COST]] -> 2018.4 | V14: 7. Criteria based statistical fxns
A15: ORD-1012 | B15: 45631 | C15: CUST-118 | D15: Corporate | E15: South | F15: Electronics | G15: Tablet | H15: 5 | I15: 42.43 | J15: =I15*H15 -> 212.15 | K15: =YEAR(Table2[[#This Row],[Order Date]]) -> 2024 | L15: =MONTH(Table2[[#This Row],[Order Date]]) -> 12 | M15: =WEEKDAY(Table2[[#This Row],[Order Date]]) -> 5 | N15: =VLOOKUP(Table2[[#This Row],[Product]], Product_Lookup!$A$2:$B$26, 2, FALSE) -> 146.06 | O15: =Table2[[#This Row],[Product Cost(VL)]]*Table2[[#This Row],[Quantity]] -> 730.3 | P15: =Table2[[#This Row],[Sales Amount]]-Table2[[#This Row],[ PRODUCT COST]] -> -518.15 | V15: TOTAL SALES FOR ELECTRONICS | W15: =SUMIF(F:F,"Electronics",J:J) -> 62548.21
A16: ORD-1013 | B16: 45632 | C16: CUST-119 | D16: Home Office | E16: South | F16: Office Supplies | G16: Desk Lamp | H16: 8 | I16: 80.01 | J16: =I16*H16 -> 640.08 | K16: =YEAR(Table2[[#This Row],[Order Date]]) -> 2024 | L16: =MONTH(Table2[[#This Row],[Order Date]]) -> 12 | M16: =WEEKDAY(Table2[[#This Row],[Order Date]]) -> 6 | N16: =VLOOKUP(Table2[[#This Row],[Product]], Product_Lookup!$A$2:$B$26, 2, FALSE) -> 101.96 | O16: =Table2[[#This Row],[Product Cost(VL)]]*Table2[[#This Row],[Quantity]] -> 815.68 | P16: =Table2[[#This Row],[Sales Amount]]-Table2[[#This Row],[ PRODUCT COST]] -> -175.6 | V16: AVERAGE SALES FOR NORTH REGION | W16: =AVERAGEIF(E:E,"North",J:J) -> 2368.0911
A17: ORD-1014 | B17: 45633 | C17: CUST-120 | D17: Home Office | E17: Central | F17: Toys | G17: Puzzle | H17: 10 | I17: 219.93 | J17: =I17*H17 -> 2199.3 | K17: =YEAR(Table2[[#This Row],[Order Date]]) -> 2024 | L17: =MONTH(Table2[[#This Row],[Order Date]]) -> 12 | M17: =WEEKDAY(Table2[[#This Row],[Order Date]]) -> 7 | N17: =VLOOKUP(Table2[[#This Row],[Product]], Product_Lookup!$A$2:$B$26, 2, FALSE) -> 46.19 | O17: =Table2[[#This Row],[Product Cost(VL)]]*Table2[[#This Row],[Quantity]] -> 461.9 | P17: =Table2[[#This Row],[Sales Amount]]-Table2[[#This Row],[ PRODUCT COST]] -> 1737.4 | V17: COUNT ORDERS WITH QUANTITY>5 | W17: =COUNTIF(H:H, ">5") -> 142
A18: ORD-1015 | B18: 45634 | C18: CUST-121 | D18: Home Office | E18: East | F18: clothing | G18: Jeans | H18: 8 | I18: 54.55 | J18: =I18*H18 -> 436.4 | K18: =YEAR(Table2[[#This Row],[Order Date]]) -> 2024 | L18: =MONTH(Table2[[#This Row],[Order Date]]) -> 12 | M18: =WEEKDAY(Table2[[#This Row],[Order Date]]) -> 1 | N18: =VLOOKUP(Table2[[#This Row],[Product]], Product_Lookup!$A$2:$B$26, 2, FALSE) -> 33.22 | O18: =Table2[[#This Row],[Product Cost(VL)]]*Table2[[#This Row],[Quantity]] -> 265.76 | P18: =Table2[[#This Row],[Sales Amount]]-Table2[[#This Row],[ PRODUCT COST]] -> 170.64 | V18: TOTAL PROFIT FOR CLOTHING(WEST) | W18: =SUMIFS(P:P,F:F,"Clothing",E:E,"West") -> 12152.31
A19: ORD-1016 | B19: 45635 | C19: CUST-122 | D19: Home Office | E19: South | F19: Clothing | G19: Sweater | H19: 2 | I19: 198.54 | J19: =I19*H19 -> 397.08 | K19: =YEAR(Table2[[#This Row],[Order Date]]) -> 2024 | L19: =MONTH(Table2[[#This Row],[Order Date]]) -> 12 | M19: =WEEKDAY(Table2[[#This Row],[Order Date]]) -> 2 | N19: =VLOOKUP(Table2[[#This Row],[Product]], Product_Lookup!$A$2:$B$26, 2, FALSE) -> 84.57 | O19: =Table2[[#This Row],[Product Cost(VL)]]*Table2[[#This Row],[Quantity]] -> 169.14 | P19: =Table2[[#This Row],[Sales Amount]]-Table2[[#This Row],[ PRODUCT COST]] -> 227.94
A20: ORD-1017 | B20: 45636 | C20: CUST-123 | D20: Consumer | E20: Central | F20: Home & Kitchen | G20: Air Fryer | H20: 11 | I20: 363.15 | J20: =I20*H20 -> 3994.65 | K20: =YEAR(Table2[[#This Row],[Order Date]]) -> 2024 | L20: =MONTH(Table2[[#This Row],[Order Date]]) -> 12 | M20: =WEEKDAY(Table2[[#This Row],[Order Date]]) -> 3 | N20: =VLOOKUP(Table2[[#This Row],[Product]], Product_Lookup!$A$2:$B$26, 2, FALSE) -> 211.9 | O20: =Table2[[#This Row],[Product Cost(VL)]]*Table2[[#This Row],[Quantity]] -> 2330.9 | P20: =Table2[[#This Row],[Sales Amount]]-Table2[[#This Row],[ PRODUCT COST]] -> 1663.75
A21: ORD-1018 | B21: 45637 | C21: CUST-124 | D21: Corporate | E21: East | F21: home & kitchen | G21: Blender | H21: 7 | I21: 87.5 | J21: =I21*H21 -> 612.5 | K21: =YEAR(Table2[[#This Row],[Order Date]]) -> 2024 | L21: =MONTH(Table2[[#This Row],[Order Date]]) -> 12 | M21: =WEEKDAY(Table2[[#This Row],[Order Date]]) -> 4 | N21: =VLOOKUP(Table2[[#This Row],[Product]], Product_Lookup!$A$2:$B$26, 2, FALSE) -> 156.44 | O21: =Table2[[#This Row],[Product Cost(VL)]]*Table2[[#This Row],[Quantity]] -> 1095.08 | P21: =Table2[[#This Row],[Sales Amount]]-Table2[[#This Row],[ PRODUCT COST]] -> -482.58
A22: ORD-1019 | B22: 45638 | C22: CUST-125 | D22: Consumer | E22: Central | F22: Clothing | G22: Socks | H22: 14 | I22: 316.4 | J22: =I22*H22 -> 4429.6 | K22: =YEAR(Table2[[#This Row],[Order Date]]) -> 2024 | L22: =MONTH(Table2[[#This Row],[Order Date]]) -> 12 | M22: =WEEKDAY(Table2[[#This Row],[Order Date]]) -> 5 | N22: =VLOOKUP(Table2[[#This Row],[Product]], Product_Lookup!$A$2:$B$26, 2, FALSE) -> 201.32 | O22: =Table2[[#This Row],[Product Cost(VL)]]*Table2[[#This Row],[Quantity]] -> 2818.48 | P22: =Table2[[#This Row],[Sales Amount]]-Table2[[#This Row],[ PRODUCT COST]] -> 1611.12
A23: ORD-1020 | B23: 45639 | C23: CUST-126 | D23: Corporate | E23: Central | F23: Clothing | G23: Jeans | H23: 13 | I23: 89.16 | J23: =I23*H23 -> 1159.08 | K23: =YEAR(Table2[[#This Row],[Order Date]]) -> 2024 | L23: =MONTH(Table2[[#This Row],[Order Date]]) -> 12 | M23: =WEEKDAY(Table2[[#This Row],[Order Date]]) -> 6 | N23: =VLOOKUP(Table2[[#This Row],[Product]], Product_Lookup!$A$2:$B$26, 2, FALSE) -> 33.22 | O23: =Table2[[#This Row],[Product Cost(VL)]]*Table2[[#This Row],[Quantity]] -> 431.86 | P23: =Table2[[#This Row],[Sales Amount]]-Table2[[#This Row],[ PRODUCT COST]] -> 727.22
A24: ORD-1021 | B24: 45640 | C24: CUST-127 | D24: Corporate | E24: North | F24: Toys | G24: Puzzle | H24: 1 | I24: 64.82 | J24: =I24*H24 -> 64.82 | K24: =YEAR(Table2[[#This Row],[Order Date]]) -> 2024 | L24: =MONTH(Table2[[#This Row],[Order Date]]) -> 12 | M24: =WEEKDAY(Table2[[#This Row],[Order Date]]) -> 7 | N24: =VLOOKUP(Table2[[#This Row],[Product]], Product_Lookup!$A$2:$B$26, 2, FALSE) -> 46.19 | O24: =Table2[[#This Row],[Product Cost(VL)]]*Table2[[#This Row],[Quantity]] -> 46.19 | P24: =Table2[[#This Row],[Sales Amount]]-Table2[[#This Row],[ PRODUCT COST]] -> 18.63
A25: ORD-1022 | B25: 45641 | C25: CUST-128 | D25: Home Office | E25: South | F25: Electronics | G25: Smartphone | H25: 2 | I25: 51.97 | J25: =I25*H25 -> 103.94 | K25: =YEAR(Table2[[#This Row],[Order Date]]) -> 2024 | L25: =MONTH(Table2[[#This Row],[Order Date]]) -> 12 | M25: =WEEKDAY(Table2[[#This Row],[Order Date]]) -> 1 | N25: =VLOOKUP(Table2[[#This Row],[Product]], Product_Lookup!$A$2:$B$26, 2, FALSE) -> 216.22 | O25: =Table2[[#This Row],[Product Cost(VL)]]*Table2[[#This Row],[Quantity]] -> 432.44 | P25: =Table2[[#This Row],[Sales Amount]]-Table2[[#This Row],[ PRODUCT COST]] -> -328.5
A26: ORD-1023 | B26: 45642 | C26: CUST-129 | D26: Home Office | E26: Central | F26: Clothing | G26: Jeans | H26: 8 | I26: 473.96 | J26: =I26*H26 -> 3791.68 | K26: =YEAR(Table2[[#This Row],[Order Date]]) -> 2024 | L26: =MONTH(Table2[[#This Row],[Order Date]]) -> 12 | M26: =WEEKDAY(Table2[[#This Row],[Order Date]]) -> 2 | N26: =VLOOKUP(Table2[[#This Row],[Product]], Product_Lookup!$A$2:$B$26, 2, FALSE) -> 33.22 | O26: =Table2[[#This Row],[Product Cost(VL)]]*Table2[[#This Row],[Quantity]] -> 265.76 | P26: =Table2[[#This Row],[Sales Amount]]-Table2[[#This Row],[ PRODUCT COST]] -> 3525.92
A27: ORD-1024 | B27: 45643 | C27: CUST-130 | D27: Consumer | E27: Central | F27: Toys | G27: Lego Set | H27: 15 | I27: 274.26 | J27: =I27*H27 -> 4113.9 | K27: =YEAR(Table2[[#This Row],[Order Date]]) -> 2024 | L27: =MONTH(Table2[[#This Row],[Order Date]]) -> 12 | M27: =WEEKDAY(Table2[[#This Row],[Order Date]]) -> 3 | N27: =VLOOKUP(Table2[[#This Row],[Product]], Product_Lookup!$A$2:$B$26, 2, FALSE) -> 130.07 | O27: =Table2[[#This Row],[Product Cost(VL)]]*Table2[[#This Row],[Quantity]] -> 1951.05 | P27: =Table2[[#This Row],[Sales Amount]]-Table2[[#This Row],[ PRODUCT COST]] -> 2162.85
A28: ORD-1025 | B28: 45644 | C28: CUST-131 | D28: Home Office | E28: South | F28: Home & Kitchen | G28: Vacuum | H28: 11 | I28: 192.98 | J28: =I28*H28 -> 2122.78 | K28: =YEAR(Table2[[#This Row],[Order Date]]) -> 2024 | L28: =MONTH(Table2[[#This Row],[Order Date]]) -> 12 | M28: =WEEKDAY(Table2[[#This Row],[Order Date]]) -> 4 | N28: =VLOOKUP(Table2[[#This Row],[Product]], Product_Lookup!$A$2:$B$26, 2, FALSE) -> 26.59 | O28: =Table2[[#This Row],[Product Cost(VL)]]*Table2[[#This Row],[Quantity]] -> 292.49 | P28: =Table2[[#This Row],[Sales Amount]]-Table2[[#This Row],[ PRODUCT COST]] -> 1830.29
A29: ORD-1026 | B29: 45645 | C29: CUST-132 | D29: Consumer | E29: North | F29: Clothing | G29: Jeans | H29: 6 | I29: 20.31 | J29: =I29*H29 -> 121.86 | K29: =YEAR(Table2[[#This Row],[Order Date]]) -> 2024 | L29: =MONTH(Table2[[#This Row],[Order Date]]) -> 12 | M29: =WEEKDAY(Table2[[#This Row],[Order Date]]) -> 5 | N29: =VLOOKUP(Table2[[#This Row],[Product]], Product_Lookup!$A$2:$B$26, 2, FALSE) -> 33.22 | O29: =Table2[[#This Row],[Product Cost(VL)]]*Table2[[#This Row],[Quantity]] -> 199.32 | P29: =Table2[[#This Row],[Sales Amount]]-Table2[[#This Row],[ PRODUCT COST]] -> -77.46
A30: ORD-1027 | B30: 45646 | C30: CUST-133 | D30: Consumer | E30: Central | F30: Clothing | G30: T-Shirt | H30: 12 | I30: 319.24 | J30: =I30*H30 -> 3830.88 | K30: =YEAR(Table2[[#This Row],[Order Date]]) -> 2024 | L30: =MONTH(Table2[[#This Row],[Order Date]]) -> 12 | M30: =WEEKDAY(Table2[[#This Row],[Order Date]]) -> 6 | N30: =VLOOKUP(Table2[[#This Row],[Product]], Product_Lookup!$A$2:$B$26, 2, FALSE) -> 107.34 | O30: =Table2[[#This Row],[Product Cost(VL)]]*Table2[[#This Row],[Quantity]] -> 1288.08 | P30: =Table2[[#This Row],[Sales Amount]]-Table2[[#This Row],[ PRODUCT COST]] -> 2542.8
... A207: ORD-1204 | B207: 45823 | C207: CUST-310 | D207: Consumer | E207: West | F207: Home & Kitchen | G207: Coffee Maker | H207: 4 | I207: 479.03 | J207: =I207*H207 -> 1916.12 | K207: =YEAR(Table2[[#This Row],[Order Date]]) -> 2025 | L207: =MONTH(Table2[[#This Row],[Order Date]]) -> 6 | M207: =WEEKDAY(Table2[[#This Row],[Order Date]]) -> 1 | N207: =VLOOKUP(Table2[[#This Row],[Product]], Product_Lookup!$A$2:$B$26, 2, FALSE) -> 230.34 | O207: =Table2[[#This Row],[Product Cost(VL)]]*Table2[[#This Row],[Quantity]] -> 921.36 | P207: =Table2[[#This Row],[Sales Amount]]-Table2[[#This Row],[ PRODUCT COST]] -> 994.76
A208: Total | H208: =SUBTOTAL(109,Table2[Quantity]) -> 1702 | I208: =SUBTOTAL(109,Table2[Unit Price]) -> 50287.2 | J208: =SUBTOTAL(109,Table2[Sales Amount]) -> 423108.02 | N208: =SUBTOTAL(109,Table2[Product Cost(VL)]) -> 25776.06 | O208: =SUBTOTAL(109,Table2[[ PRODUCT COST]]) -> 212207.49 | P208: =SUBTOTAL(109,Table2[PROFIT]) -> 210900.53

Sheet  Cell Referencing 
C1: Sales Amount | D1: 5% | E1: 10% | F1: 20% | G1: 30% | H1: Order Status . | I1: types of orders | J1: IF,AND | K1: QUANTITY | L1: CUSYOMER ID | U1: DISOUNT USING IF | W1: Discount Amount | X1: %DISCOUNT
C2: =DATA_CLEANING!J3 -> 313.48 | D2: =$C2*D$1 -> 15.674 | E2: =$C2*E$1 -> 31.348 | F2: =$C2*F$1 -> 62.696 | G2: =$C2*G$1 -> 94.044 | H2: =IF(Table3[[#This Row],[Sales Amount]]>500,"Large Order", "Standard Order") -> Standard Order | I2: =IF(AND(Table3[[#This Row],[Sales Amount]]>750,DATA_CLEANING!H3>5), "GREAT ORDER", "LOW ORDER") -> LOW ORDER | L2: =DATA_CLEANING!C2 -> Customer ID | U2: DISCOUNT PRICE | W2: 1000 | X2: 0.05
C3: =DATA_CLEANING!J4 -> 78.38 | D3: =$C3*D$1 -> 3.919 | E3: =$C3*E$1 -> 7.838 | F3: =$C3*F$1 -> 15.676 | G3: =$C3*G$1 -> 23.514 | H3: =IF(Table3[[#This Row],[Sales Amount]]>500,"Large Order", "Standard Order") -> Standard Order | I3: =IF(AND(Table3[[#This Row],[Sales Amount]]>750,DATA_CLEANING!H4>5), "GREAT ORDER", "LOW ORDER") -> LOW ORDER | K3: =DATA_CLEANING!H3 -> 4 | L3: =DATA_CLEANING!C3 -> CUST-106 | U3: =VALUE(DATA_CLEANING!J3)* IF(VALUE(DATA_CLEANING!J3)>=6000,30%, IF(VALUE(DATA_CLEANING!J3)>=5000,20%, IF(VALUE(DATA_CLEANING!J3)>=3000,10%, IF(VALUE(DATA_CLEANING!J3)>=1000,5%,0)))) -> 0 | W3: 3000 | X3: 0.1
C4: =DATA_CLEANING!J5 -> 1443.4 | D4: =$C4*D$1 -> 72.17 | E4: =$C4*E$1 -> 144.34 | F4: =$C4*F$1 -> 288.68 | G4: =$C4*G$1 -> 433.02 | H4: =IF(Table3[[#This Row],[Sales Amount]]>500,"Large Order", "Standard Order") -> Large Order | I4: =IF(AND(Table3[[#This Row],[Sales Amount]]>750,DATA_CLEANING!H5>5), "GREAT ORDER", "LOW ORDER") -> LOW ORDER | K4: =DATA_CLEANING!H4 -> 1 | L4: =DATA_CLEANING!C4 -> CUST-107 | U4: =VALUE(DATA_CLEANING!J4)* IF(VALUE(DATA_CLEANING!J4)>=6000,30%, IF(VALUE(DATA_CLEANING!J4)>=5000,20%, IF(VALUE(DATA_CLEANING!J4)>=3000,10%, IF(VALUE(DATA_CLEANING!J4)>=1000,5%,0)))) -> 0 | W4: 5000 | X4: 0.2
C5: =DATA_CLEANING!J6 -> 2033.1 | D5: =$C5*D$1 -> 101.655 | E5: =$C5*E$1 -> 203.31 | F5: =$C5*F$1 -> 406.62 | G5: =$C5*G$1 -> 609.93 | H5: =IF(Table3[[#This Row],[Sales Amount]]>500,"Large Order", "Standard Order") -> Large Order | I5: =IF(AND(Table3[[#This Row],[Sales Amount]]>750,DATA_CLEANING!H6>5), "GREAT ORDER", "LOW ORDER") -> LOW ORDER | K5: =DATA_CLEANING!H5 -> 4 | L5: =DATA_CLEANING!C5 -> CUST-108 | U5: =VALUE(DATA_CLEANING!J5)* IF(VALUE(DATA_CLEANING!J5)>=6000,30%, IF(VALUE(DATA_CLEANING!J5)>=5000,20%, IF(VALUE(DATA_CLEANING!J5)>=3000,10%, IF(VALUE(DATA_CLEANING!J5)>=1000,5%,0)))) -> 72.17 | W5: 6000 | X5: 0.3
C6: =DATA_CLEANING!J7 -> 1916.12 | D6: =$C6*D$1 -> 95.806 | E6: =$C6*E$1 -> 191.612 | F6: =$C6*F$1 -> 383.224 | G6: =$C6*G$1 -> 574.836 | H6: =IF(Table3[[#This Row],[Sales Amount]]>500,"Large Order", "Standard Order") -> Large Order | I6: =IF(AND(Table3[[#This Row],[Sales Amount]]>750,DATA_CLEANING!H7>5), "GREAT ORDER", "LOW ORDER") -> LOW ORDER | K6: =DATA_CLEANING!H6 -> 5 | L6: =DATA_CLEANING!C6 -> CUST-109 | U6: =VALUE(DATA_CLEANING!J6)* IF(VALUE(DATA_CLEANING!J6)>=6000,30%, IF(VALUE(DATA_CLEANING!J6)>=5000,20%, IF(VALUE(DATA_CLEANING!J6)>=3000,10%, IF(VALUE(DATA_CLEANING!J6)>=1000,5%,0)))) -> 101.655
C7: =DATA_CLEANING!J8 -> 2499.56 | D7: =$C7*D$1 -> 124.978 | E7: =$C7*E$1 -> 249.956 | F7: =$C7*F$1 -> 499.912 | G7: =$C7*G$1 -> 749.868 | H7: =IF(Table3[[#This Row],[Sales Amount]]>500,"Large Order", "Standard Order") -> Large Order | I7: =IF(AND(Table3[[#This Row],[Sales Amount]]>750,DATA_CLEANING!H8>5), "GREAT ORDER", "LOW ORDER") -> GREAT ORDER | K7: =DATA_CLEANING!H7 -> 4 | L7: =DATA_CLEANING!C7 -> CUST-110 | U7: =VALUE(DATA_CLEANING!J7)* IF(VALUE(DATA_CLEANING!J7)>=6000,30%, IF(VALUE(DATA_CLEANING!J7)>=5000,20%, IF(VALUE(DATA_CLEANING!J7)>=3000,10%, IF(VALUE(DATA_CLEANING!J7)>=1000,5%,0)))) -> 95.806
C8: =DATA_CLEANING!J9 -> 561 | D8: =$C8*D$1 -> 28.05 | E8: =$C8*E$1 -> 56.1 | F8: =$C8*F$1 -> 112.2 | G8: =$C8*G$1 -> 168.3 | H8: =IF(Table3[[#This Row],[Sales Amount]]>500,"Large Order", "Standard Order") -> Large Order | I8: =IF(AND(Table3[[#This Row],[Sales Amount]]>750,DATA_CLEANING!H9>5), "GREAT ORDER", "LOW ORDER") -> LOW ORDER | K8: =DATA_CLEANING!H8 -> 14 | L8: =DATA_CLEANING!C8 -> CUST-111 | U8: =VALUE(DATA_CLEANING!J8)* IF(VALUE(DATA_CLEANING!J8)>=6000,30%, IF(VALUE(DATA_CLEANING!J8)>=5000,20%, IF(VALUE(DATA_CLEANING!J8)>=3000,10%, IF(VALUE(DATA_CLEANING!J8)>=1000,5%,0)))) -> 124.978
C9: =DATA_CLEANING!J10 -> 64.9 | D9: =$C9*D$1 -> 3.245 | E9: =$C9*E$1 -> 6.49 | F9: =$C9*F$1 -> 12.98 | G9: =$C9*G$1 -> 19.47 | H9: =IF(Table3[[#This Row],[Sales Amount]]>500,"Large Order", "Standard Order") -> Standard Order | I9: =IF(AND(Table3[[#This Row],[Sales Amount]]>750,DATA_CLEANING!H10>5), "GREAT ORDER", "LOW ORDER") -> LOW ORDER | K9: =DATA_CLEANING!H9 -> 2 | L9: =DATA_CLEANING!C9 -> CUST-112 | U9: =VALUE(DATA_CLEANING!J9)* IF(VALUE(DATA_CLEANING!J9)>=6000,30%, IF(VALUE(DATA_CLEANING!J9)>=5000,20%, IF(VALUE(DATA_CLEANING!J9)>=3000,10%, IF(VALUE(DATA_CLEANING!J9)>=1000,5%,0)))) -> 0
C10: =DATA_CLEANING!J11 -> 1160.85 | D10: =$C10*D$1 -> 58.0425 | E10: =$C10*E$1 -> 116.085 | F10: =$C10*F$1 -> 232.17 | G10: =$C10*G$1 -> 348.255 | H10: =IF(Table3[[#This Row],[Sales Amount]]>500,"Large Order", "Standard Order") -> Large Order | I10: =IF(AND(Table3[[#This Row],[Sales Amount]]>750,DATA_CLEANING!H11>5), "GREAT ORDER", "LOW ORDER") -> LOW ORDER | K10: =DATA_CLEANING!H10 -> 2 | L10: =DATA_CLEANING!C10 -> CUST-113 | U10: =VALUE(DATA_CLEANING!J10)* IF(VALUE(DATA_CLEANING!J10)>=6000,30%, IF(VALUE(DATA_CLEANING!J10)>=5000,20%, IF(VALUE(DATA_CLEANING!J10)>=3000,10%, IF(VALUE(DATA_CLEANING!J10)>=1000,5%,0)))) -> 0
C11: =DATA_CLEANING!J12 -> 1769.45 | D11: =$C11*D$1 -> 88.4725 | E11: =$C11*E$1 -> 176.945 | F11: =$C11*F$1 -> 353.89 | G11: =$C11*G$1 -> 530.835 | H11: =IF(Table3[[#This Row],[Sales Amount]]>500,"Large Order", "Standard Order") -> Large Order | I11: =IF(AND(Table3[[#This Row],[Sales Amount]]>750,DATA_CLEANING!H12>5), "GREAT ORDER", "LOW ORDER") -> LOW ORDER | K11: =DATA_CLEANING!H11 -> 5 | L11: =DATA_CLEANING!C11 -> CUST-114 | U11: =VALUE(DATA_CLEANING!J11)* IF(VALUE(DATA_CLEANING!J11)>=6000,30%, IF(VALUE(DATA_CLEANING!J11)>=5000,20%, IF(VALUE(DATA_CLEANING!J11)>=3000,10%, IF(VALUE(DATA_CLEANING!J11)>=1000,5%,0)))) -> 58.0425
C12: =DATA_CLEANING!J13 -> 1559.52 | D12: =$C12*D$1 -> 77.976 | E12: =$C12*E$1 -> 155.952 | F12: =$C12*F$1 -> 311.904 | G12: =$C12*G$1 -> 467.856 | H12: =IF(Table3[[#This Row],[Sales Amount]]>500,"Large Order", "Standard Order") -> Large Order | I12: =IF(AND(Table3[[#This Row],[Sales Amount]]>750,DATA_CLEANING!H13>5), "GREAT ORDER", "LOW ORDER") -> GREAT ORDER | K12: =DATA_CLEANING!H12 -> 5 | L12: =DATA_CLEANING!C12 -> CUST-115 | U12: =VALUE(DATA_CLEANING!J12)* IF(VALUE(DATA_CLEANING!J12)>=6000,30%, IF(VALUE(DATA_CLEANING!J12)>=5000,20%, IF(VALUE(DATA_CLEANING!J12)>=3000,10%, IF(VALUE(DATA_CLEANING!J12)>=1000,5%,0)))) -> 88.4725
C13: =DATA_CLEANING!J14 -> 2538 | D13: =$C13*D$1 -> 126.9 | E13: =$C13*E$1 -> 253.8 | F13: =$C13*F$1 -> 507.6 | G13: =$C13*G$1 -> 761.4 | H13: =IF(Table3[[#This Row],[Sales Amount]]>500,"Large Order", "Standard Order") -> Large Order | I13: =IF(AND(Table3[[#This Row],[Sales Amount]]>750,DATA_CLEANING!H14>5), "GREAT ORDER", "LOW ORDER") -> GREAT ORDER | K13: =DATA_CLEANING!H13 -> 12 | L13: =DATA_CLEANING!C13 -> CUST-116 | U13: =VALUE(DATA_CLEANING!J13)* IF(VALUE(DATA_CLEANING!J13)>=6000,30%, IF(VALUE(DATA_CLEANING!J13)>=5000,20%, IF(VALUE(DATA_CLEANING!J13)>=3000,10%, IF(VALUE(DATA_CLEANING!J13)>=1000,5%,0)))) -> 77.976
C14: =DATA_CLEANING!J15 -> 212.15 | D14: =$C14*D$1 -> 10.6075 | E14: =$C14*E$1 -> 21.215 | F14: =$C14*F$1 -> 42.43 | G14: =$C14*G$1 -> 63.645 | H14: =IF(Table3[[#This Row],[Sales Amount]]>500,"Large Order", "Standard Order") -> Standard Order | I14: =IF(AND(Table3[[#This Row],[Sales Amount]]>750,DATA_CLEANING!H15>5), "GREAT ORDER", "LOW ORDER") -> LOW ORDER | K14: =DATA_CLEANING!H14 -> 6 | L14: =DATA_CLEANING!C14 -> CUST-117 | U14: =VALUE(DATA_CLEANING!J14)* IF(VALUE(DATA_CLEANING!J14)>=6000,30%, IF(VALUE(DATA_CLEANING!J14)>=5000,20%, IF(VALUE(DATA_CLEANING!J14)>=3000,10%, IF(VALUE(DATA_CLEANING!J14)>=1000,5%,0)))) -> 126.9
C15: =DATA_CLEANING!J16 -> 640.08 | D15: =$C15*D$1 -> 32.004 | E15: =$C15*E$1 -> 64.008 | F15: =$C15*F$1 -> 128.016 | G15: =$C15*G$1 -> 192.024 | H15: =IF(Table3[[#This Row],[Sales Amount]]>500,"Large Order", "Standard Order") -> Large Order | I15: =IF(AND(Table3[[#This Row],[Sales Amount]]>750,DATA_CLEANING!H16>5), "GREAT ORDER", "LOW ORDER") -> LOW ORDER | K15: =DATA_CLEANING!H15 -> 5 | L15: =DATA_CLEANING!C15 -> CUST-118 | U15: =VALUE(DATA_CLEANING!J15)* IF(VALUE(DATA_CLEANING!J15)>=6000,30%, IF(VALUE(DATA_CLEANING!J15)>=5000,20%, IF(VALUE(DATA_CLEANING!J15)>=3000,10%, IF(VALUE(DATA_CLEANING!J15)>=1000,5%,0)))) -> 0
C16: =DATA_CLEANING!J17 -> 2199.3 | D16: =$C16*D$1 -> 109.965 | E16: =$C16*E$1 -> 219.93 | F16: =$C16*F$1 -> 439.86 | G16: =$C16*G$1 -> 659.79 | H16: =IF(Table3[[#This Row],[Sales Amount]]>500,"Large Order", "Standard Order") -> Large Order | I16: =IF(AND(Table3[[#This Row],[Sales Amount]]>750,DATA_CLEANING!H17>5), "GREAT ORDER", "LOW ORDER") -> GREAT ORDER | K16: =DATA_CLEANING!H16 -> 8 | L16: =DATA_CLEANING!C16 -> CUST-119 | U16: =VALUE(DATA_CLEANING!J16)* IF(VALUE(DATA_CLEANING!J16)>=6000,30%, IF(VALUE(DATA_CLEANING!J16)>=5000,20%, IF(VALUE(DATA_CLEANING!J16)>=3000,10%, IF(VALUE(DATA_CLEANING!J16)>=1000,5%,0)))) -> 0
C17: =DATA_CLEANING!J18 -> 436.4 | D17: =$C17*D$1 -> 21.82 | E17: =$C17*E$1 -> 43.64 | F17: =$C17*F$1 -> 87.28 | G17: =$C17*G$1 -> 130.92 | H17: =IF(Table3[[#This Row],[Sales Amount]]>500,"Large Order", "Standard Order") -> Standard Order | I17: =IF(AND(Table3[[#This Row],[Sales Amount]]>750,DATA_CLEANING!H18>5), "GREAT ORDER", "LOW ORDER") -> LOW ORDER | K17: =DATA_CLEANING!H17 -> 10 | L17: =DATA_CLEANING!C17 -> CUST-120 | U17: =VALUE(DATA_CLEANING!J17)* IF(VALUE(DATA_CLEANING!J17)>=6000,30%, IF(VALUE(DATA_CLEANING!J17)>=5000,20%, IF(VALUE(DATA_CLEANING!J17)>=3000,10%, IF(VALUE(DATA_CLEANING!J17)>=1000,5%,0)))) -> 109.965
... C207: =DATA_CLEANING!J208 -> 423108.02 | D207: =$C207*D$1 -> 21155.401 | E207: =$C207*E$1 -> 42310.802 | F207: =$C207*F$1 -> 84621.604 | G207: =$C207*G$1 -> 126932.41 | H207: =IF(Table3[[#This Row],[Sales Amount]]>500,"Large Order", "Standard Order") -> Large Order | I207: =IF(AND(Table3[[#This Row],[Sales Amount]]>750,DATA_CLEANING!H208>5), "GREAT ORDER", "LOW ORDER") -> GREAT ORDER | K207: =DATA_CLEANING!H207 -> 4 | L207: =DATA_CLEANING!C207 -> CUST-310 | U207: =VALUE(DATA_CLEANING!J207)* IF(VALUE(DATA_CLEANING!J207)>=6000,30%, IF(VALUE(DATA_CLEANING!J207)>=5000,20%, IF(VALUE(DATA_CLEANING!J207)>=3000,10%, IF(VALUE(DATA_CLEANING!J207)>=1000,5%,0)))) -> 95.806
L208: =DATA_CLEANING!C208 -> 0
L209: =DATA_CLEANING!C209 -> 0
L210: =DATA_CLEANING!C210 -> 0
L211: =DATA_CLEANING!C211 -> 0
L212: =DATA_CLEANING!C212 -> 0

Sheet Product_Lookup
A1: Product | B1: Product Cost
A2: Laptop | B2: 230.68
A3: Smartphone | B3: 216.22
A4: Tablet | B4: 146.06
A5: Monitor | B5: 145.48
A6: Headphones | B6: 178.83
A7: T-Shirt | B7: 107.34
A8: Jeans | B8: 33.22
A9: Jacket | B9: 10.11
A10: Sweater | B10: 84.57
A11: Socks | B11: 201.32
A12: Blender | B12: 156.44
A13: Toaster | B13: 208.85
... A26: Doll | B26: 32.94

Sheet DATA_VALIDATION
A1: Column1 | B1: Column2
A2: Region selection | B2: Target Sales
A3: =DATA_CLEANING!E3 -> North | B3: 567
A4: =DATA_CLEANING!E4 -> Central | B4: 432
A5: =DATA_CLEANING!E5 -> Central | B5: 100
A6: =DATA_CLEANING!E6 -> West | B6: 390
A7: =DATA_CLEANING!E7 -> West | B7: 10000
A8: =DATA_CLEANING!E8 -> North
A9: =DATA_CLEANING!E9 -> West
A10: =DATA_CLEANING!E10 -> East
A11: =DATA_CLEANING!E11 -> North
A12: =DATA_CLEANING!E12 -> East
A13: =DATA_CLEANING!E13 -> North
A14: =DATA_CLEANING!E14 -> East
A15: =DATA_CLEANING!E15 -> South
A16: =DATA_CLEANING!E16 -> South
A17: =DATA_CLEANING!E17 -> Central
A18: =DATA_CLEANING!E18 -> East
A19: =DATA_CLEANING!E19 -> South
... A207: =DATA_CLEANING!E207 -> West
